Workbook

Sheet Infrastructure Data
A1: month_date | B1: month_label | C1: year | D1: month | E1: indicator_code | F1: indicator_name | G1: major_section | H1: sub_section | I1: infra_category | J1: hierarchy_level | K1: count_lakh | L1: count_actual | M1: count_source_col | N1: value_source_col | O1: raw_count_str | P1: raw_value_str | Q1: anomaly_flag | R1: notes
A2: 43770 | B2: 43770 | C2: 2019 | D2: 11 | E2: ATMS_BANK_OWNED | F2: 3.1 Bank owned ATMs $ | G2: Payment System Infrastructures | H2: II Retail | I2: ATM Terminals Deployed | J2: Component | K2: 2.1 | L2: 210000 | M2: c130 | N2: c131 | O2: 2.10 | P2: - | Q2: NONE
A3: 43770 | B3: 43770 | C3: 2019 | D3: 11 | E3: ATMS_TOTAL_DEPLOYED | F3: 3 Number of ATMs (3.1 to 3.2) | G3: Payment System Infrastructures | H3: II Retail | I3: ATM Terminals Deployed | J3: Category_Total | K3: 2.32 | L3: 232000 | M3: c128 | N3: c129 | O3: 2.32 | P3: - | Q3: NONE
A4: 43770 | B4: 43770 | C4: 2019 | D4: 11 | E4: ATMS_WHITE_LABEL | F4: 3.2 White Label ATMs $ | G4: Payment System Infrastructures | H4: II Retail | I4: ATM Terminals Deployed | J4: Component | K4: 0.22 | L4: 22000 | M4: c132 | N4: c133 | O4: 0.22 | P4: - | Q4: NONE
A5: 43770 | B5: 43770 | C5: 2019 | D5: 11 | E5: BHARAT_QR_DEPLOYED | F5: 6 Bharat QR @ | G5: Payment System Infrastructures | H5: II Retail | I5: Merchant Acquiring Touchpoints | J5: Component | K5: 15.94 | L5: 1594000 | M5: c138 | N5: c139 | O5: 15.94 | P5: - | Q5: NONE
A6: 43770 | B6: 43770 | C6: 2019 | D6: 11 | E6: CARDS_CREDIT_OUTSTANDING | F6: 1.1 Credit Cards | G6: Payment System Infrastructures | H6: II Retail | I6: Payment Cards in Force | J6: Component | K6: 544.11 | L6: 54411000 | M6: c118 | N6: c119 | O6: 544.11 | P6: - | Q6: NONE
A7: 43770 | B7: 43770 | C7: 2019 | D7: 11 | E7: CARDS_DEBIT_OUTSTANDING | F7: 1.2 Debit Cards | G7: Payment System Infrastructures | H7: II Retail | I7: Payment Cards in Force | J7: Component | K7: 8307.59 | L7: 830759000 | M7: c120 | N7: c121 | O7: 8307.59 | P7: - | Q7: NONE
A8: 43770 | B8: 43770 | C8: 2019 | D8: 11 | E8: CARDS_TOTAL_OUTSTANDING | F8: 1 Number of Cards (1.1 to 1.2) | G8: Payment System Infrastructures | H8: II Retail | I8: Payment Cards in Force | J8: Category_Total | K8: 8851.69 | L8: 885169000 | M8: c116 | N8: c117 | O8: 8851.69 | P8: - | Q8: NONE
A9: 43770 | B9: 43770 | C9: 2019 | D9: 11 | E9: MICRO_ATMS_DEPLOYED | F9: 4 Number of Micro ATMs @ | G9: Payment System Infrastructures | H9: II Retail | I9: Micro-ATM Footprint | J9: Component | K9: 3.74 | L9: 374000 | M9: c134 | N9: c135 | O9: 3.74 | P9: - | Q9: NONE
A10: 43770 | B10: 43770 | C10: 2019 | D10: 11 | E10: POS_TERMINALS_DEPLOYED | F10: 5 Number of PoS Terminals | G10: Payment System Infrastructures | H10: II Retail | I10: Merchant Acquiring Touchpoints | J10: Component | K10: 41.28 | L10: 4128000 | M10: c136 | N10: c137 | O10: 41.28 | P10: - | Q10: NONE
A11: 43770 | B11: 43770 | C11: 2019 | D11: 11 | E11: PPIS_CARDS_ISSUED | F11: 2.2 Cards @ | G11: Payment System Infrastructures | H11: II Retail | I11: Prepaid Instruments in Force | J11: Component | K11: 1019.33 | L11: 101933000 | M11: c126 | N11: c127 | O11: 1019.33 | P11: - | Q11: NONE
A12: 43770 | B12: 43770 | C12: 2019 | D12: 11 | E12: PPIS_TOTAL_ISSUED | F12: 2 Number of PPIs @ (2.1 to 2.2) | G12: Payment System Infrastructures | H12: II Retail | I12: Prepaid Instruments in Force | J12: Category_Total | K12: 17263.2 | L12: 1726320000 | M12: c122 | N12: c123 | O12: 17263.20 | P12: - | Q12: NONE
A13: 43770 | B13: 43770 | C13: 2019 | D13: 11 | E13: PPIS_WALLETS_ISSUED | F13: 2.1 Wallets @ | G13: Payment System Infrastructures | H13: II Retail | I13: Prepaid Instruments in Force | J13: Component | K13: 16243.87 | L13: 1624387000 | M13: c124 | N13: c125 | O13: 16243.87 | P13: - | Q13: NONE
A14: 43770 | B14: 43770 | C14: 2019 | D14: 11 | E14: UPI_QR_STATIC_DEPLOYED | F14: 7 UPI QR * | G14: Payment System Infrastructures | H14: II Retail | I14: Merchant Acquiring Touchpoints | J14: Component | M14: c140 | N14: c141 | O14: - | P14: - | Q14: PRE_LAUNCH_NOT_REPORTED | R14: Static UPI QR tracking initiated w.e.f. September 2020 per Footnote 1 (*).
A15: 43800 | B15: 43800 | C15: 2019 | D15: 12 | E15: ATMS_BANK_OWNED | F15: 3.1 Bank owned ATMs $ | G15: Payment System Infrastructures | H15: II Retail | I15: ATM Terminals Deployed | J15: Component | K15: 2.1 | L15: 210000 | M15: c130 | N15: c131 | O15: 2.10 | P15: - | Q15: NONE
A16: 43800 | B16: 43800 | C16: 2019 | D16: 12 | E16: ATMS_TOTAL_DEPLOYED | F16: 3 Number of ATMs (3.1 to 3.2) | G16: Payment System Infrastructures | H16: II Retail | I16: ATM Terminals Deployed | J16: Category_Total | K16: 2.32 | L16: 232000 | M16: c128 | N16: c129 | O16: 2.32 | P16: - | Q16: NONE
A17: 43800 | B17: 43800 | C17: 2019 | D17: 12 | E17: ATMS_WHITE_LABEL | F17: 3.2 White Label ATMs $ | G17: Payment System Infrastructures | H17: II Retail | I17: ATM Terminals Deployed | J17: Component | K17: 0.22 | L17: 22000 | M17: c132 | N17: c133 | O17: 0.22 | P17: - | Q17: NONE
A18: 43800 | B18: 43800 | C18: 2019 | D18: 12 | E18: BHARAT_QR_DEPLOYED | F18: 6 Bharat QR @ | G18: Payment System Infrastructures | H18: II Retail | I18: Merchant Acquiring Touchpoints | J18: Component | K18: 17.13 | L18: 1713000 | M18: c138 | N18: c139 | O18: 17.13 | P18: - | Q18: NONE
A19: 43800 | B19: 43800 | C19: 2019 | D19: 12 | E19: CARDS_CREDIT_OUTSTANDING | F19: 1.1 Credit Cards | G19: Payment System Infrastructures | H19: II Retail | I19: Payment Cards in Force | J19: Component | K19: 553.33 | L19: 55333000 | M19: c118 | N19: c119 | O19: 553.33 | P19: - | Q19: NONE
A20: 43800 | B20: 43800 | C20: 2019 | D20: 12 | E20: CARDS_DEBIT_OUTSTANDING | F20: 1.2 Debit Cards | G20: Payment System Infrastructures | H20: II Retail | I20: Payment Cards in Force | J20: Component | K20: 8053.24 | L20: 805324000 | M20: c120 | N20: c121 | O20: 8053.24 | P20: - | Q20: NONE
A21: 43800 | B21: 43800 | C21: 2019 | D21: 12 | E21: CARDS_TOTAL_OUTSTANDING | F21: 1 Number of Cards (1.1 to 1.2) | G21: Payment System Infrastructures | H21: II Retail | I21: Payment Cards in Force | J21: Category_Total | K21: 8606.57 | L21: 860657000 | M21: c116 | N21: c117 | O21: 8606.57 | P21: - | Q21: NONE
A22: 43800 | B22: 43800 | C22: 2019 | D22: 12 | E22: MICRO_ATMS_DEPLOYED | F22: 4 Number of Micro ATMs @ | G22: Payment System Infrastructures | H22: II Retail | I22: Micro-ATM Footprint | J22: Component | K22: 3.81 | L22: 381000 | M22: c134 | N22: c135 | O22: 3.81 | P22: - | Q22: NONE
A23: 43800 | B23: 43800 | C23: 2019 | D23: 12 | E23: POS_TERMINALS_DEPLOYED | F23: 5 Number of PoS Terminals | G23: Payment System Infrastructures | H23: II Retail | I23: Merchant Acquiring Touchpoints | J23: Component | K23: 42.49 | L23: 4249000 | M23: c136 | N23: c137 | O23: 42.49 | P23: - | Q23: NONE
A24: 43800 | B24: 43800 | C24: 2019 | D24: 12 | E24: PPIS_CARDS_ISSUED | F24: 2.2 Cards @ | G24: Payment System Infrastructures | H24: II Retail | I24: Prepaid Instruments in Force | J24: Component | K24: 1009.75 | L24: 100975000 | M24: c126 | N24: c127 | O24: 1009.75 | P24: - | Q24: NONE
A25: 43800 | B25: 43800 | C25: 2019 | D25: 12 | E25: PPIS_TOTAL_ISSUED | F25: 2 Number of PPIs @ (2.1 to 2.2) | G25: Payment System Infrastructures | H25: II Retail | I25: Prepaid Instruments in Force | J25: Category_Total | K25: 17625.43 | L25: 1762543000 | M25: c122 | N25: c123 | O25: 17625.43 | P25: - | Q25: NONE
A26: 43800 | B26: 43800 | C26: 2019 | D26: 12 | E26: PPIS_WALLETS_ISSUED | F26: 2.1 Wallets @ | G26: Payment System Infrastructures | H26: II Retail | I26: Prepaid Instruments in Force | J26: Component | K26: 16615.68 | L26: 1661568000 | M26: c124 | N26: c125 | O26: 16615.68 | P26: - | Q26: NONE
A27: 43800 | B27: 43800 | C27: 2019 | D27: 12 | E27: UPI_QR_STATIC_DEPLOYED | F27: 7 UPI QR * | G27: Payment System Infrastructures | H27: II Retail | I27: Merchant Acquiring Touchpoints | J27: Component | M27: c140 | N27: c141 | O27: - | P27: - | Q27: PRE_LAUNCH_NOT_REPORTED | R27: Static UPI QR tracking initiated w.e.f. September 2020 per Footnote 1 (*).
A28: 43831 | B28: 43831 | C28: 2020 | D28: 1 | E28: ATMS_BANK_OWNED | F28: 3.1 Bank owned ATMs $ | G28: Payment System Infrastructures | H28: II Retail | I28: ATM Terminals Deployed | J28: Component | K28: 2.1 | L28: 210000 | M28: c130 | N28: c131 | O28: 2.10 | P28: - | Q28: NONE
A29: 43831 | B29: 43831 | C29: 2020 | D29: 1 | E29: ATMS_TOTAL_DEPLOYED | F29: 3 Number of ATMs (3.1 to 3.2) | G29: Payment System Infrastructures | H29: II Retail | I29: ATM Terminals Deployed | J29: Category_Total | K29: 2.33 | L29: 233000 | M29: c128 | N29: c129 | O29: 2.33 | P29: - | Q29: NONE
A30: 43831 | B30: 43831 | C30: 2020 | D30: 1 | E30: ATMS_WHITE_LABEL | F30: 3.2 White Label ATMs $ | G30: Payment System Infrastructures | H30: II Retail | I30: ATM Terminals Deployed | J30: Component | K30: 0.23 | L30: 23000 | M30: c132 | N30: c133 | O30: 0.23 | P30: - | Q30: NONE
A31: 43831 | B31: 43831 | C31: 2020 | D31: 1 | E31: BHARAT_QR_DEPLOYED | F31: 6 Bharat QR @ | G31: Payment System Infrastructures | H31: II Retail | I31: Merchant Acquiring Touchpoints | J31: Component | K31: 17.79 | L31: 1779000 | M31: c138 | N31: c139 | O31: 17.79 | P31: - | Q31: NONE
A32: 43831 | B32: 43831 | C32: 2020 | D32: 1 | E32: CARDS_CREDIT_OUTSTANDING | F32: 1.1 Credit Cards | G32: Payment System Infrastructures | H32: II Retail | I32: Payment Cards in Force | J32: Component | K32: 561.2 | L32: 56120000 | M32: c118 | N32: c119 | O32: 561.20 | P32: - | Q32: NONE
A33: 43831 | B33: 43831 | C33: 2020 | D33: 1 | E33: CARDS_DEBIT_OUTSTANDING | F33: 1.2 Debit Cards | G33: Payment System Infrastructures | H33: II Retail | I33: Payment Cards in Force | J33: Component | K33: 8164.1 | L33: 816410000 | M33: c120 | N33: c121 | O33: 8164.10 | P33: - | Q33: NONE
A34: 43831 | B34: 43831 | C34: 2020 | D34: 1 | E34: CARDS_TOTAL_OUTSTANDING | F34: 1 Number of Cards (1.1 to 1.2) | G34: Payment System Infrastructures | H34: II Retail | I34: Payment Cards in Force | J34: Category_Total | K34: 8725.3 | L34: 872530000 | M34: c116 | N34: c117 | O34: 8725.30 | P34: - | Q34: NONE
A35: 43831 | B35: 43831 | C35: 2020 | D35: 1 | E35: MICRO_ATMS_DEPLOYED | F35: 4 Number of Micro ATMs @ | G35: Payment System Infrastructures | H35: II Retail | I35: Micro-ATM Footprint | J35: Component | K35: 3.96 | L35: 396000 | M35: c134 | N35: c135 | O35: 3.96 | P35: - | Q35: NONE
A36: 43831 | B36: 43831 | C36: 2020 | D36: 1 | E36: POS_TERMINALS_DEPLOYED | F36: 5 Number of PoS Terminals | G36: Payment System Infrastructures | H36: II Retail | I36: Merchant Acquiring Touchpoints | J36: Component | K36: 42.92 | L36: 4292000 | M36: c136 | N36: c137 | O36: 42.92 | P36: - | Q36: NONE
A37: 43831 | B37: 43831 | C37: 2020 | D37: 1 | E37: PPIS_CARDS_ISSUED | F37: 2.2 Cards @ | G37: Payment System Infrastructures | H37: II Retail | I37: Prepaid Instruments in Force | J37: Component | K37: 999.43 | L37: 99943000 | M37: c126 | N37: c127 | O37: 999.43 | P37: - | Q37: NONE
A38: 43831 | B38: 43831 | C38: 2020 | D38: 1 | E38: PPIS_TOTAL_ISSUED | F38: 2 Number of PPIs @ (2.1 to 2.2) | G38: Payment System Infrastructures | H38: II Retail | I38: Prepaid Instruments in Force | J38: Category_Total | K38: 17574.74 | L38: 1757474000 | M38: c122 | N38: c123 | O38: 17574.74 | P38: - | Q38: NONE
A39: 43831 | B39: 43831 | C39: 2020 | D39: 1 | E39: PPIS_WALLETS_ISSUED | F39: 2.1 Wallets @ | G39: Payment System Infrastructures | H39: II Retail | I39: Prepaid Instruments in Force | J39: Component | K39: 16575.31 | L39: 1657531000 | M39: c124 | N39: c125 | O39: 16575.31 | P39: - | Q39: NONE
A40: 43831 | B40: 43831 | C40: 2020 | D40: 1 | E40: UPI_QR_STATIC_DEPLOYED | F40: 7 UPI QR * | G40: Payment System Infrastructures | H40: II Retail | I40: Merchant Acquiring Touchpoints | J40: Component | M40: c140 | N40: c141 | O40: - | P40: - | Q40: PRE_LAUNCH_NOT_REPORTED | R40: Static UPI QR tracking initiated w.e.f. September 2020 per Footnote 1 (*).
...

Sheet Data Dictionary
A1: column_id | B1: column_index | C1: indicator_code | D1: indicator_name | E1: indicator_type | F1: major_section | G1: sub_section | H1: channel_group | I1: hierarchy_level | J1: metric_type | K1: unit_of_measurement | L1: ats_eligible | M1: footnote_symbols | N1: source_header_raw | O1: cleaning_action | P1: known_anomalies
A2: src_file | B2: 0 | C2: SRC_FILE | D2: Source file identifier | E2: METADATA | F2: File Wrapper Metadata | G2: N/A | H2: Metadata | I2: Metadata | J2: Metadata Attribute | K2: Source attribution string | L2: FALSE | N2: src_file | O2: Preserved for source traceability. | P2: None
A3: tab | B3: 1 | C3: TAB | D3: Workbook worksheet tab name | E3: METADATA | F3: File Wrapper Metadata | G3: N/A | H3: Metadata | I3: Metadata | J3: Metadata Attribute | K3: RBI tab name string | L3: FALSE | N3: tab | O3: Preserved for source traceability. | P3: None
A4: period | B4: 2 | C4: PERIOD | D4: Data release scope | E4: METADATA | F4: File Wrapper Metadata | G4: N/A | H4: Metadata | I4: Metadata | J4: Metadata Attribute | K4: Historical span scope string | L4: FALSE | N4: period | O4: Preserved for source traceability. | P4: None
A5: row_no | B5: 3 | C5: ROW_NO | D5: Sequential spreadsheet line index | E5: METADATA | F5: File Wrapper Metadata | G5: N/A | H5: Metadata | I5: Metadata | J5: Metadata Attribute | K5: Integer line number (1-93) | L5: FALSE | N5: row_no | O5: Preserved for source traceability. | P5: None
A6: c1 | B6: 4 | C6: MONTH_YEAR | D6: Month/Year Observation Period | E6: TEMPORAL | F6: Temporal Dimension | G6: N/A | H6: Calendar Time | I6: Dimension | J6: Date Anchor | K6: ISO Date (YYYY-MM-01) | L6: FALSE | N6: Month/Year | O6: Parsed MMM-YYYY strings to first day of month (YYYY-MM-01). | P6: Reverse chronological ordering in raw source (Jul-2026 to Nov-2019).
A7: c2 | B7: 5 | C7: CCIL_TOTAL_VOL | D7: 1 CCIL Operated Systems (1.1 to 1.3) [Volume] | E7: TRANSACTION | F7: A. Settlement Systems | G7: Financial Market Infrastructures (FMIs) | H7: Wholesale Settlement (CCIL) | I7: Category_Total | J7: Transaction Volume | K7: Lakh (100,000 transactions) | L7: TRUE | N7: L4: A. Settlement Systems | L5: Financial Market Infrastructures (FMIs) | L6: 1 CCIL Operated Systems (1.1 to 1.3) | L7: Volume (Lakh) | O7: Parsed to numeric float. Converted '-' to NaN. Imputed Sep-2023 for PPI Total. | P7: None
A8: c3 | B8: 6 | C8: CCIL_TOTAL_VAL | D8: 1 CCIL Operated Systems (1.1 to 1.3) [Value] | E8: TRANSACTION | F8: A. Settlement Systems | G8: Financial Market Infrastructures (FMIs) | H8: Wholesale Settlement (CCIL) | I8: Category_Total | J8: Transaction Value | K8: Rupees Crores (â‚¹ 10,000,000 INR) | L8: TRUE | N8: L4: | L5: | L6: | L7: Value( Rupees Crores ) | O8: Parsed to numeric float. Converted '-' to NaN. | P8: None
A9: c4 | B9: 7 | C9: CCIL_GSEC_TOTAL_VOL | D9: 1.1 Govt. Securities Clearing (1.1.1 to 1.1.3) [Volume] | E9: TRANSACTION | F9: A. Settlement Systems | G9: Financial Market Infrastructures (FMIs) | H9: Wholesale Settlement (CCIL) | I9: Subtotal | J9: Transaction Volume | K9: Lakh (100,000 transactions) | L9: TRUE | N9: L4: | L5: | L6: 1.1 Govt. Securities Clearing (1.1.1 to 1.1.3) | L7: Volume (Lakh) | O9: Parsed to numeric float. Converted '-' to NaN. Imputed Sep-2023 for PPI Total. | P9: None
A10: c5 | B10: 8 | C10: CCIL_GSEC_TOTAL_VAL | D10: 1.1 Govt. Securities Clearing (1.1.1 to 1.1.3) [Value] | E10: TRANSACTION | F10: A. Settlement Systems | G10: Financial Market Infrastructures (FMIs) | H10: Wholesale Settlement (CCIL) | I10: Subtotal | J10: Transaction Value | K10: Rupees Crores (â‚¹ 10,000,000 INR) | L10: TRUE | N10: L4: | L5: | L6: | L7: Value( Rupees Crores ) | O10: Parsed to numeric float. Converted '-' to NaN. | P10: None
A11: c6 | B11: 9 | C11: CCIL_GSEC_OUTRIGHT_VOL | D11: 1.1.1 Outright [Volume] | E11: TRANSACTION | F11: A. Settlement Systems | G11: Financial Market Infrastructures (FMIs) | H11: Wholesale Settlement (CCIL) | I11: Component | J11: Transaction Volume | K11: Lakh (100,000 transactions) | L11: TRUE | N11: L4: | L5: | L6: 1.1.1 Outright | L7: Volume (Lakh) | O11: Parsed to numeric float. Converted '-' to NaN. Imputed Sep-2023 for PPI Total. | P11: None
A12: c7 | B12: 10 | C12: CCIL_GSEC_OUTRIGHT_VAL | D12: 1.1.1 Outright [Value] | E12: TRANSACTION | F12: A. Settlement Systems | G12: Financial Market Infrastructures (FMIs) | H12: Wholesale Settlement (CCIL) | I12: Component | J12: Transaction Value | K12: Rupees Crores (â‚¹ 10,000,000 INR) | L12: TRUE | N12: L4: | L5: | L6: | L7: Value( Rupees Crores ) | O12: Parsed to numeric float. Converted '-' to NaN. | P12: None
A13: c8 | B13: 11 | C13: CCIL_GSEC_REPO_VOL | D13: 1.1.2 Repo [Volume] | E13: TRANSACTION | F13: A. Settlement Systems | G13: Financial Market Infrastructures (FMIs) | H13: Wholesale Settlement (CCIL) | I13: Component | J13: Transaction Volume | K13: Lakh (100,000 transactions) | L13: TRUE | N13: L4: | L5: | L6: 1.1.2 Repo | L7: Volume (Lakh) | O13: Parsed to numeric float. Converted '-' to NaN. Imputed Sep-2023 for PPI Total. | P13: None
... A18: c13 | B18: 16 | C18: CCIL_FOREX_CLEARING_VAL | D18: 1.2 Forex Clearing [Value] | E18: TRANSACTION | F18: A. Settlement Systems | G18: Financial Market Infrastructures (FMIs) | H18: Wholesale Settlement (CCIL) | I18: Component | J18: Transaction Value | K18: Rupees Crores (â‚¹ 10,000,000 INR) | L18: TRUE | N18: L4: | L5: | L6: | L7: Value( Rupees Crores ) | O18: Parsed to numeric float. Converted '-' to NaN. | P18: None
A19: c14 | B19: 17 | C19: CCIL_RUPEE_DERIVATIVES_VOL | D19: 1.3 Rupee Derivatives @ [Volume] | E19: TRANSACTION | F19: A. Settlement Systems | G19: Financial Market Infrastructures (FMIs) | H19: Wholesale Settlement (CCIL) | I19: Component | J19: Transaction Volume | K19: Lakh (100,000 transactions) | L19: TRUE | M19: @ | N19: L4: | L5: | L6: 1.3 Rupee Derivatives @ | L7: Volume (Lakh) | O19: Parsed to numeric float. Converted '-' to NaN. Imputed Sep-2023 for PPI Total. | P19: None
A20: c15 | B20: 18 | C20: CCIL_RUPEE_DERIVATIVES_VAL | D20: 1.3 Rupee Derivatives @ [Value] | E20: TRANSACTION | F20: A. Settlement Systems | G20: Financial Market Infrastructures (FMIs) | H20: Wholesale Settlement (CCIL) | I20: Component | J20: Transaction Value | K20: Rupees Crores (â‚¹ 10,000,000 INR) | L20: TRUE | M20: @ | N20: L4: | L5: | L6: | L7: Value( Rupees Crores ) | O20: Parsed to numeric float. Converted '-' to NaN. | P20: None
A21: c16 | B21: 19 | C21: RTGS_TOTAL_VOL | D21: 1 Credit Transfers - RTGS (1.1 to 1.2) [Volume] | E21: TRANSACTION | F21: B. Payment Systems | G21: I Financial Market Infrastructures (FMIs) | H21: Large-Value Credit Transfers (RTGS) | I21: Category_Total | J21: Transaction Volume | K21: Lakh (100,000 transactions) | L21: TRUE | N21: L4: B. Payment Systems | L5: I Financial Market Infrastructures (FMIs) | L6: 1 Credit Transfers - RTGS (1.1 to 1.2) | L7: Volume (Lakh) | O21: Parsed to numeric float. Converted '-' to NaN. Imputed Sep-2023 for PPI Total. | P21: None
A22: c17 | B22: 20 | C22: RTGS_TOTAL_VAL | D22: 1 Credit Transfers - RTGS (1.1 to 1.2) [Value] | E22: TRANSACTION | F22: B. Payment Systems | G22: I Financial Market Infrastructures (FMIs) | H22: Large-Value Credit Transfers (RTGS) | I22: Category_Total | J22: Transaction Value | K22: Rupees Crores (â‚¹ 10,000,000 INR) | L22: TRUE | N22: L4: | L5: | L6: | L7: Value( Rupees Crores ) | O22: Parsed to numeric float. Converted '-' to NaN. | P22: None
A23: c18 | B23: 21 | C23: RTGS_CUSTOMER_VOL | D23: 1.1 Customer Transactions [Volume] | E23: TRANSACTION | F23: B. Payment Systems | G23: I Financial Market Infrastructures (FMIs) | H23: Large-Value Credit Transfers (RTGS) | I23: Component | J23: Transaction Volume | K23: Lakh (100,000 transactions) | L23: TRUE | N23: L4: | L5: | L6: 1.1 Customer Transactions | L7: Volume (Lakh) | O23: Parsed to numeric float. Converted '-' to NaN. Imputed Sep-2023 for PPI Total. | P23: None
A24: c19 | B24: 22 | C24: RTGS_CUSTOMER_VAL | D24: 1.1 Customer Transactions [Value] | E24: TRANSACTION | F24: B. Payment Systems | G24: I Financial Market Infrastructures (FMIs) | H24: Large-Value Credit Transfers (RTGS) | I24: Component | J24: Transaction Value | K24: Rupees Crores (â‚¹ 10,000,000 INR) | L24: TRUE | N24: L4: | L5: | L6: | L7: Value( Rupees Crores ) | O24: Parsed to numeric float. Converted '-' to NaN. | P24: None
A25: c20 | B25: 23 | C25: RTGS_INTERBANK_VOL | D25: 1.2 Interbank Transactions [Volume] | E25: TRANSACTION | F25: B. Payment Systems | G25: I Financial Market Infrastructures (FMIs) | H25: Large-Value Credit Transfers (RTGS) | I25: Component | J25: Transaction Volume | K25: Lakh (100,000 transactions) | L25: TRUE | N25: L4: | L5: | L6: 1.2 Interbank Transactions | L7: Volume (Lakh) | O25: Parsed to numeric float. Converted '-' to NaN. Imputed Sep-2023 for PPI Total. | P25: None
A26: c21 | B26: 24 | C26: RTGS_INTERBANK_VAL | D26: 1.2 Interbank Transactions [Value] | E26: TRANSACTION | F26: B. Payment Systems | G26: I Financial Market Infrastructures (FMIs) | H26: Large-Value Credit Transfers (RTGS) | I26: Component | J26: Transaction Value | K26: Rupees Crores (â‚¹ 10,000,000 INR) | L26: TRUE | N26: L4: | L5: | L6: | L7: Value( Rupees Crores ) | O26: Parsed to numeric float. Converted '-' to NaN. | P26: None
A27: c22 | B27: 25 | C27: RETAIL_CREDIT_TRANSFERS_TOTAL_VOL | D27: 2 Credit Transfers - Retail (2.1 to 2.7) [Volume] | E27: TRANSACTION | F27: B. Payment Systems | G27: II Retail | H27: Retail Credit Transfers | I27: Category_Total | J27: Transaction Volume | K27: Lakh (100,000 transactions) | L27: TRUE | N27: L4: | L5: II Retail | L6: 2 Credit Transfers - Retail (2.1 to 2.7) | L7: Volume (Lakh) | O27: Parsed to numeric float. Converted '-' to NaN. Imputed Sep-2023 for PPI Total. | P27: None
A28: c23 | B28: 26 | C28: RETAIL_CREDIT_TRANSFERS_TOTAL_VAL | D28: 2 Credit Transfers - Retail (2.1 to 2.7) [Value] | E28: TRANSACTION | F28: B. Payment Systems | G28: II Retail | H28: Retail Credit Transfers | I28: Category_Total | J28: Transaction Value | K28: Rupees Crores (â‚¹ 10,000,000 INR) | L28: TRUE | N28: L4: | L5: | L6: | L7: Value( Rupees Crores ) | O28: Parsed to numeric float. Converted '-' to NaN. | P28: None
A29: c24 | B29: 27 | C29: AEPS_FUND_TRANSFERS_VOL | D29: 2.1 AePS (Fund Transfers) @ [Volume] | E29: TRANSACTION | F29: B. Payment Systems | G29: II Retail | H29: Retail Credit Transfers | I29: Component | J29: Transaction Volume | K29: Lakh (100,000 transactions) | L29: TRUE | M29: @ | N29: L4: | L5: | L6: 2.1 AePS (Fund Transfers) @ | L7: Volume (Lakh) | O29: Parsed to numeric float. Converted '-' to NaN. Imputed Sep-2023 for PPI Total. | P29: None
A30: c25 | B30: 28 | C30: AEPS_FUND_TRANSFERS_VAL | D30: 2.1 AePS (Fund Transfers) @ [Value] | E30: TRANSACTION | F30: B. Payment Systems | G30: II Retail | H30: Retail Credit Transfers | I30: Component | J30: Transaction Value | K30: Rupees Crores (â‚¹ 10,000,000 INR) | L30: TRUE | M30: @ | N30: L4: | L5: | L6: | L7: Value( Rupees Crores ) | O30: Parsed to numeric float. Converted '-' to NaN. | P30: None
A31: c26 | B31: 29 | C31: APBS_VOL | D31: 2.2 APBS $ [Volume] | E31: TRANSACTION | F31: B. Payment Systems | G31: II Retail | H31: Retail Credit Transfers | I31: Component | J31: Transaction Volume | K31: Lakh (100,000 transactions) | L31: TRUE | M31: $ | N31: L4: | L5: | L6: 2.2 APBS $ | L7: Volume (Lakh) | O31: Parsed to numeric float. Converted '-' to NaN. Imputed Sep-2023 for PPI Total. | P31: None
A32: c27 | B32: 30 | C32: APBS_VAL | D32: 2.2 APBS $ [Value] | E32: TRANSACTION | F32: B. Payment Systems | G32: II Retail | H32: Retail Credit Transfers | I32: Component | J32: Transaction Value | K32: Rupees Crores (â‚¹ 10,000,000 INR) | L32: TRUE | M32: $ | N32: L4: | L5: | L6: | L7: Value( Rupees Crores ) | O32: Parsed to numeric float. Converted '-' to NaN. | P32: None
A33: c28 | B33: 31 | C33: ECS_CREDIT_VOL | D33: 2.3 ECS Cr [Volume] | E33: TRANSACTION | F33: B. Payment Systems | G33: II Retail | H33: Retail Credit Transfers | I33: Component | J33: Transaction Volume | K33: Lakh (100,000 transactions) | L33: TRUE | N33: L4: | L5: | L6: 2.3 ECS Cr | L7: Volume (Lakh) | O33: Parsed to numeric float. Converted '-' to NaN. Imputed Sep-2023 for PPI Total. | P33: Merged into NACH on 31-Jan-2020; post-merger periods contain '-' or 0.00.
A34: c29 | B34: 32 | C34: ECS_CREDIT_VAL | D34: 2.3 ECS Cr [Value] | E34: TRANSACTION | F34: B. Payment Systems | G34: II Retail | H34: Retail Credit Transfers | I34: Component | J34: Transaction Value | K34: Rupees Crores (â‚¹ 10,000,000 INR) | L34: TRUE | N34: L4: | L5: | L6: | L7: Value( Rupees Crores ) | O34: Parsed to numeric float. Converted '-' to NaN. | P34: Merged into NACH on 31-Jan-2020; post-merger periods contain '-' or 0.00.
A35: c30 | B35: 33 | C35: IMPS_VOL | D35: 2.4 IMPS [Volume] | E35: TRANSACTION | F35: B. Payment Systems | G35: II Retail | H35: Retail Credit Transfers | I35: Component | J35: Transaction Volume | K35: Lakh (100,000 transactions) | L35: TRUE | N35: L4: | L5: | L6: 2.4 IMPS | L7: Volume (Lakh) | O35: Parsed to numeric float. Converted '-' to NaN. Imputed Sep-2023 for PPI Total. | P35: None
A36: c31 | B36: 34 | C36: IMPS_VAL | D36: 2.4 IMPS [Value] | E36: TRANSACTION | F36: B. Payment Systems | G36: II Retail | H36: Retail Credit Transfers | I36: Component | J36: Transaction Value | K36: Rupees Crores (â‚¹ 10,000,000 INR) | L36: TRUE | N36: L4: | L5: | L6: | L7: Value( Rupees Crores ) | O36: Parsed to numeric float. Converted '-' to NaN. | P36: None
A37: c32 | B37: 35 | C37: NACH_CREDIT_VOL | D37: 2.5 NACH Cr $ [Volume] | E37: TRANSACTION | F37: B. Payment Systems | G37: II Retail | H37: Retail Credit Transfers | I37: Component | J37: Transaction Volume | K37: Lakh (100,000 transactions) | L37: TRUE | M37: $ | N37: L4: | L5: | L6: 2.5 NACH Cr $ | L7: Volume (Lakh) | O37: Parsed to numeric float. Converted '-' to NaN. Imputed Sep-2023 for PPI Total. | P37: None
A38: c33 | B38: 36 | C38: NACH_CREDIT_VAL | D38: 2.5 NACH Cr $ [Value] | E38: TRANSACTION | F38: B. Payment Systems | G38: II Retail | H38: Retail Credit Transfers | I38: Component | J38: Transaction Value | K38: Rupees Crores (â‚¹ 10,000,000 INR) | L38: TRUE | M38: $ | N38: L4: | L5: | L6: | L7: Value( Rupees Crores ) | O38: Parsed to numeric float. Converted '-' to NaN. | P38: None
A39: c34 | B39: 37 | C39: NEFT_VOL | D39: 2.6 NEFT [Volume] | E39: TRANSACTION | F39: B. Payment Systems | G39: II Retail | H39: Retail Credit Transfers | I39: Component | J39: Transaction Volume | K39: Lakh (100,000 transactions) | L39: TRUE | N39: L4: | L5: | L6: 2.6 NEFT | L7: Volume (Lakh) | O39: Parsed to numeric float. Converted '-' to NaN. Imputed Sep-2023 for PPI Total. | P39: None
A40: c35 | B40: 38 | C40: NEFT_VAL | D40: 2.6 NEFT [Value] | E40: TRANSACTION | F40: B. Payment Systems | G40: II Retail | H40: Retail Credit Transfers | I40: Component | J40: Transaction Value | K40: Rupees Crores (â‚¹ 10,000,000 INR) | L40: TRUE | N40: L4: | L5: | L6: | L7: Value( Rupees Crores ) | O40: Parsed to numeric float. Converted '-' to NaN. | P40: None
A41: c36 | B41: 39 | C41: UPI_VOL | D41: 2.7 UPI @ [Volume] | E41: TRANSACTION | F41: B. Payment Systems | G41: II Retail | H41: Retail Credit Transfers | I41: Component | J41: Transaction Volume | K41: Lakh (100,000 transactions) | L41: TRUE | M41: @ | N41: L4: | L5: | L6: 2.7 UPI @ | L7: Volume (Lakh) | O41: Parsed to numeric float. Converted '-' to NaN. Imputed Sep-2023 for PPI Total. | P41: None
A42: c37 | B42: 40 | C42: UPI_VAL | D42: 2.7 UPI @ [Value] | E42: TRANSACTION | F42: B. Payment Systems | G42: II Retail | H42: Retail Credit Transfers | I42: Component | J42: Transaction Value | K42: Rupees Crores (â‚¹ 10,000,000 INR) | L42: TRUE | M42: @ | N42: L4: | L5: | L6: | L7: Value( Rupees Crores ) | O42: Parsed to numeric float. Converted '-' to NaN. | P42: None
A43: c38 | B43: 41 | C43: UPI_USSD_VOL | D43: 2.7.1 of which USSD @ [Volume] | E43: TRANSACTION | F43: B. Payment Systems | G43: II Retail | H43: Retail Credit Transfers | I43: Sub_Component | J43: Transaction Volume | K43: Lakh (100,000 transactions) | L43: TRUE | M43: @ | N43: L4: | L5: | L6: 2.7.1 of which USSD @ | L7: Volume (Lakh) | O43: Parsed to numeric float. Converted '-' to NaN. Imputed Sep-2023 for PPI Total. | P43: None
A44: c39 | B44: 42 | C44: UPI_USSD_VAL | D44: 2.7.1 of which USSD @ [Value] | E44: TRANSACTION | F44: B. Payment Systems | G44: II Retail | H44: Retail Credit Transfers | I44: Sub_Component | J44: Transaction Value | K44: Rupees Crores (â‚¹ 10,000,000 INR) | L44: TRUE | M44: @ | N44: L4: | L5: | L6: | L7: Value( Rupees Crores ) | O44: Parsed to numeric float. Converted '-' to NaN. | P44: None
...

Sheet Cleaning Exceptions
A1: exception_id | B1: month_date | C1: month_label | D1: source_column | E1: indicator_code | F1: indicator_name | G1: raw_value | H1: cleaned_value | I1: exception_category | J1: severity | K1: resolution_applied | L1: audit_justification
A2: EXC_0036 | B2: 43770 | C2: 43770 | D2: c140 | E2: UPI_QR_STATIC_DEPLOYED | F2: 7 UPI QR * | G2: - | I2: PRE_LAUNCH_TRACKING | J2: INFO | K2: Preserved as NaN/None with PRE_LAUNCH flag | L2: Tracking officially commenced in September 2020 per RBI footnote marker (*).
A3: EXC_0035 | B3: 43800 | C3: 43800 | D3: c140 | E3: UPI_QR_STATIC_DEPLOYED | F3: 7 UPI QR * | G3: - | I3: PRE_LAUNCH_TRACKING | J3: INFO | K3: Preserved as NaN/None with PRE_LAUNCH flag | L3: Tracking officially commenced in September 2020 per RBI footnote marker (*).
A4: EXC_0034 | B4: 43831 | C4: 43831 | D4: c140 | E4: UPI_QR_STATIC_DEPLOYED | F4: 7 UPI QR * | G4: - | I4: PRE_LAUNCH_TRACKING | J4: INFO | K4: Preserved as NaN/None with PRE_LAUNCH flag | L4: Tracking officially commenced in September 2020 per RBI footnote marker (*).
A5: EXC_0033 | B5: 43862 | C5: 43862 | D5: c140 | E5: UPI_QR_STATIC_DEPLOYED | F5: 7 UPI QR * | G5: - | I5: PRE_LAUNCH_TRACKING | J5: INFO | K5: Preserved as NaN/None with PRE_LAUNCH flag | L5: Tracking officially commenced in September 2020 per RBI footnote marker (*).
A6: EXC_0032 | B6: 43891 | C6: 43891 | D6: c140 | E6: UPI_QR_STATIC_DEPLOYED | F6: 7 UPI QR * | G6: - | I6: PRE_LAUNCH_TRACKING | J6: INFO | K6: Preserved as NaN/None with PRE_LAUNCH flag | L6: Tracking officially commenced in September 2020 per RBI footnote marker (*).
A7: EXC_0031 | B7: 43922 | C7: 43922 | D7: c140 | E7: UPI_QR_STATIC_DEPLOYED | F7: 7 UPI QR * | G7: - | I7: PRE_LAUNCH_TRACKING | J7: INFO | K7: Preserved as NaN/None with PRE_LAUNCH flag | L7: Tracking officially commenced in September 2020 per RBI footnote marker (*).
A8: EXC_0030 | B8: 43952 | C8: 43952 | D8: c140 | E8: UPI_QR_STATIC_DEPLOYED | F8: 7 UPI QR * | G8: - | I8: PRE_LAUNCH_TRACKING | J8: INFO | K8: Preserved as NaN/None with PRE_LAUNCH flag | L8: Tracking officially commenced in September 2020 per RBI footnote marker (*).
A9: EXC_0029 | B9: 43983 | C9: 43983 | D9: c140 | E9: UPI_QR_STATIC_DEPLOYED | F9: 7 UPI QR * | G9: - | I9: PRE_LAUNCH_TRACKING | J9: INFO | K9: Preserved as NaN/None with PRE_LAUNCH flag | L9: Tracking officially commenced in September 2020 per RBI footnote marker (*).
A10: EXC_0028 | B10: 44013 | C10: 44013 | D10: c140 | E10: UPI_QR_STATIC_DEPLOYED | F10: 7 UPI QR * | G10: - | I10: PRE_LAUNCH_TRACKING | J10: INFO | K10: Preserved as NaN/None with PRE_LAUNCH flag | L10: Tracking officially commenced in September 2020 per RBI footnote marker (*).
A11: EXC_0027 | B11: 44044 | C11: 44044 | D11: c140 | E11: UPI_QR_STATIC_DEPLOYED | F11: 7 UPI QR * | G11: - | I11: PRE_LAUNCH_TRACKING | J11: INFO | K11: Preserved as NaN/None with PRE_LAUNCH flag | L11: Tracking officially commenced in September 2020 per RBI footnote marker (*).
A12: EXC_0026 | B12: 45170 | C12: 45170 | D12: c64 | E12: PPI_TOTAL | F12: 5 Prepaid Payment Instruments (5.1 to 5.2) | G12: - | H12: 6143.17 | I12: MISSING_TOTAL_IMPUTATION | J12: MEDIUM | K12: Imputed component sum: Wallets (c66) + PPI Cards (c68) | L12: Raw source reported '-' for PPI total volume in Sep-2023 while reported value (23667.78) matches Wallets value (19944.07) + Cards value (3723.71) = 23667.78. Arithmetic and structure justify imputation.
A13: EXC_0025 | B13: 45292 | C13: 45292 | D13: c141 | E13: UPI_QR_STATIC_DEPLOYED | F13: 7 UPI QR * | G13: 3379.94 | H13: 3379.94 | I13: DISPLACED_INFRASTRUCTURE_VALUE | J13: HIGH | K13: Preserved raw value in raw_value_str; flagged record; excluded from count metrics | L13: UPI QR code count is stored in c140 (3213.79 Lakh). The non-zero value in c141 (3379.94) represents an uncorrected upstream reporting artifact / next-month volume displacement. Infrastructure has no rupee monetary value.
A14: EXC_0024 | B14: 45323 | C14: 45323 | D14: c141 | E14: UPI_QR_STATIC_DEPLOYED | F14: 7 UPI QR * | G14: 3540.62 | H14: 3540.62 | I14: DISPLACED_INFRASTRUCTURE_VALUE | J14: HIGH | K14: Preserved raw value in raw_value_str; flagged record; excluded from count metrics | L14: UPI QR code count is stored in c140 (3371.80 Lakh). The non-zero value in c141 (3540.62) represents an uncorrected upstream reporting artifact / next-month volume displacement. Infrastructure has no rupee monetary value.
A15: EXC_0023 | B15: 45352 | C15: 45352 | D15: c141 | E15: UPI_QR_STATIC_DEPLOYED | F15: 7 UPI QR * | G15: 3606.58 | H15: 3606.58 | I15: DISPLACED_INFRASTRUCTURE_VALUE | J15: HIGH | K15: Preserved raw value in raw_value_str; flagged record; excluded from count metrics | L15: UPI QR code count is stored in c140 (3434.93 Lakh). The non-zero value in c141 (3606.58) represents an uncorrected upstream reporting artifact / next-month volume displacement. Infrastructure has no rupee monetary value.
A16: EXC_0022 | B16: 45383 | C16: 45383 | D16: c141 | E16: UPI_QR_STATIC_DEPLOYED | F16: 7 UPI QR * | G16: 5766.33 | H16: 5766.33 | I16: DISPLACED_INFRASTRUCTURE_VALUE | J16: HIGH | K16: Preserved raw value in raw_value_str; flagged record; excluded from count metrics | L16: UPI QR code count is stored in c140 (5597.20 Lakh). The non-zero value in c141 (5766.33) represents an uncorrected upstream reporting artifact / next-month volume displacement. Infrastructure has no rupee monetary value.
A17: EXC_0021 | B17: 45413 | C17: 45413 | D17: c141 | E17: UPI_QR_STATIC_DEPLOYED | F17: 7 UPI QR * | G17: 5858.35 | H17: 5858.35 | I17: DISPLACED_INFRASTRUCTURE_VALUE | J17: HIGH | K17: Preserved raw value in raw_value_str; flagged record; excluded from count metrics | L17: UPI QR code count is stored in c140 (5690.84 Lakh). The non-zero value in c141 (5858.35) represents an uncorrected upstream reporting artifact / next-month volume displacement. Infrastructure has no rupee monetary value.
A18: EXC_0020 | B18: 45444 | C18: 45444 | D18: c141 | E18: UPI_QR_STATIC_DEPLOYED | F18: 7 UPI QR * | G18: 5939.27 | H18: 5939.27 | I18: DISPLACED_INFRASTRUCTURE_VALUE | J18: HIGH | K18: Preserved raw value in raw_value_str; flagged record; excluded from count metrics | L18: UPI QR code count is stored in c140 (5770.15 Lakh). The non-zero value in c141 (5939.27) represents an uncorrected upstream reporting artifact / next-month volume displacement. Infrastructure has no rupee monetary value.
A19: EXC_0019 | B19: 45474 | C19: 45474 | D19: c141 | E19: UPI_QR_STATIC_DEPLOYED | F19: 7 UPI QR * | G19: 6020.06 | H19: 6020.06 | I19: DISPLACED_INFRASTRUCTURE_VALUE | J19: HIGH | K19: Preserved raw value in raw_value_str; flagged record; excluded from count metrics | L19: UPI QR code count is stored in c140 (5851.14 Lakh). The non-zero value in c141 (6020.06) represents an uncorrected upstream reporting artifact / next-month volume displacement. Infrastructure has no rupee monetary value.
A20: EXC_0018 | B20: 45505 | C20: 45505 | D20: c141 | E20: UPI_QR_STATIC_DEPLOYED | F20: 7 UPI QR * | G20: 6086.94 | H20: 6086.94 | I20: DISPLACED_INFRASTRUCTURE_VALUE | J20: HIGH | K20: Preserved raw value in raw_value_str; flagged record; excluded from count metrics | L20: UPI QR code count is stored in c140 (5912.93 Lakh). The non-zero value in c141 (6086.94) represents an uncorrected upstream reporting artifact / next-month volume displacement. Infrastructure has no rupee monetary value.
A21: EXC_0017 | B21: 45536 | C21: 45536 | D21: c141 | E21: UPI_QR_STATIC_DEPLOYED | F21: 7 UPI QR * | G21: 6245.46 | H21: 6245.46 | I21: DISPLACED_INFRASTRUCTURE_VALUE | J21: HIGH | K21: Preserved raw value in raw_value_str; flagged record; excluded from count metrics | L21: UPI QR code count is stored in c140 (6070.79 Lakh). The non-zero value in c141 (6245.46) represents an uncorrected upstream reporting artifact / next-month volume displacement. Infrastructure has no rupee monetary value.
A22: EXC_0016 | B22: 45566 | C22: 45566 | D22: c141 | E22: UPI_QR_STATIC_DEPLOYED | F22: 7 UPI QR * | G22: 6344.98 | H22: 6344.98 | I22: DISPLACED_INFRASTRUCTURE_VALUE | J22: HIGH | K22: Preserved raw value in raw_value_str; flagged record; excluded from count metrics | L22: UPI QR code count is stored in c140 (6168.52 Lakh). The non-zero value in c141 (6344.98) represents an uncorrected upstream reporting artifact / next-month volume displacement. Infrastructure has no rupee monetary value.
A23: EXC_0015 | B23: 45597 | C23: 45597 | D23: c141 | E23: UPI_QR_STATIC_DEPLOYED | F23: 7 UPI QR * | G23: 6439.37 | H23: 6439.37 | I23: DISPLACED_INFRASTRUCTURE_VALUE | J23: HIGH | K23: Preserved raw value in raw_value_str; flagged record; excluded from count metrics | L23: UPI QR code count is stored in c140 (6261.80 Lakh). The non-zero value in c141 (6439.37) represents an uncorrected upstream reporting artifact / next-month volume displacement. Infrastructure has no rupee monetary value.
... A37: EXC_0001 | B37: 46023 | C37: 46023 | D37: c141 | E37: UPI_QR_STATIC_DEPLOYED | F37: 7 UPI QR * | G37: 7574.12 | H37: 7574.12 | I37: DISPLACED_INFRASTRUCTURE_VALUE | J37: HIGH | K37: Preserved raw value in raw_value_str; flagged record; excluded from count metrics | L37: UPI QR code count is stored in c140 (7383.80 Lakh). The non-zero value in c141 (7574.12) represents an uncorrected upstream reporting artifact / next-month volume displacement. Infrastructure has no rupee monetary value.

Sheet Transaction Data
A1: month_date | B1: month_label | C1: year | D1: month | E1: indicator_code | F1: indicator_name | G1: major_section | H1: sub_section | I1: channel_group | J1: hierarchy_level | K1: volume_lakh | L1: value_inr_crore | M1: avg_ticket_size_inr | N1: volume_source_col | O1: value_source_col | P1: raw_volume_str | Q1: raw_value_str | R1: data_status | S1: notes
A2: 43770 | B2: 43770 | C2: 2019 | D2: 11 | E2: AEPS_FUND_TRANSFERS | F2: 2.1 AePS (Fund Transfers) @ | G2: B. Payment Systems | H2: II Retail | I2: Retail Credit Transfers | J2: Component | K2: 0.64 | L2: 33.1 | M2: 5171.88 | N2: c24 | O2: c25 | P2: 0.64 | Q2: 33.10 | R2: REPORTED
A3: 43770 | B3: 43770 | C3: 2019 | D3: 11 | E3: APBS | F3: 2.2 APBS $ | G3: B. Payment Systems | H3: II Retail | I3: Retail Credit Transfers | J3: Component | K3: 1361.27 | L3: 6882.85 | M3: 505.62 | N3: c26 | O3: c27 | P3: 1361.27 | Q3: 6882.85 | R3: REPORTED
A4: 43770 | B4: 43770 | C4: 2019 | D4: 11 | E4: ATM_CASH_CREDIT_CARD | F4: 3.1 Using Credit Cards $ | G4: B. ATMs | H4: II Retail | I4: Cash Withdrawals | J4: Component | K4: 7.99 | L4: 381.17 | M4: 4770.59 | N4: c100 | O4: c101 | P4: 7.99 | Q4: 381.17 | R4: REPORTED
A5: 43770 | B5: 43770 | C5: 2019 | D5: 11 | E5: ATM_CASH_DEBIT_CARD | F5: 3.2 Using Debit Cards $ | G5: B. ATMs | H5: II Retail | I5: Cash Withdrawals | J5: Component | K5: 6236.89 | L5: 281337.85 | M5: 4510.87 | N5: c102 | O5: c103 | P5: 6236.89 | Q5: 281337.85 | R5: REPORTED
A6: 43770 | B6: 43770 | C6: 2019 | D6: 11 | E6: ATM_CASH_PREPAID_CARD | F6: 3.3 Using Pre-paid Cards $ | G6: B. ATMs | H6: II Retail | I6: Cash Withdrawals | J6: Component | K6: 27.68 | L6: 911.57 | M6: 3293.24 | N6: c104 | O6: c105 | P6: 27.68 | Q6: 911.57 | R6: REPORTED
A7: 43770 | B7: 43770 | C7: 2019 | D7: 11 | E7: ATM_CASH_TOTAL | F7: 3 Cash Withdrawal at ATMs $ (3.1 to 3.3) | G7: B. ATMs | H7: II Retail | I7: Cash Withdrawals | J7: Category_Total | K7: 6272.56 | L7: 282630.59 | M7: 4505.83 | N7: c98 | O7: c99 | P7: 6272.56 | Q7: 282630.59 | R7: REPORTED
A8: 43770 | B8: 43770 | C8: 2019 | D8: 11 | E8: BHIM_AADHAAR_PAY | F8: 3.1 BHIM Aadhaar Pay @ | G8: B. Payment Systems | H8: II Retail | I8: Retail Debit Transfers | J8: Component | K8: 6.46 | L8: 96.68 | M8: 1496.59 | N8: c42 | O8: c43 | P8: 6.46 | Q8: 96.68 | R8: REPORTED
A9: 43770 | B9: 43770 | C9: 2019 | D9: 11 | E9: CARD_PAYMENTS_TOTAL | F9: 4 Card Payments (4.1 to 4.2) | G9: B. Payment Systems | H9: II Retail | I9: Card Payments | J9: Category_Total | K9: 5942.96 | L9: 118338.93 | M9: 1991.25 | N9: c50 | O9: c51 | P9: 5942.96 | Q9: 118338.93 | R9: REPORTED
A10: 43770 | B10: 43770 | C10: 2019 | D10: 11 | E10: CCIL_FOREX_CLEARING | F10: 1.2 Forex Clearing | G10: A. Settlement Systems | H10: Financial Market Infrastructures (FMIs) | I10: Wholesale Settlement (CCIL) | J10: Component | K10: 1.74 | L10: 3525359.2 | M10: 2.0260685e+08 | N10: c12 | O10: c13 | P10: 1.74 | Q10: 3525359.16 | R10: REPORTED
A11: 43770 | B11: 43770 | C11: 2019 | D11: 11 | E11: CCIL_GSEC_OUTRIGHT | F11: 1.1.1 Outright | G11: A. Settlement Systems | H11: Financial Market Infrastructures (FMIs) | I11: Wholesale Settlement (CCIL) | J11: Component | K11: 0.63 | L11: 862103.55 | M11: 1.3684183e+08 | N11: c6 | O11: c7 | P11: 0.63 | Q11: 862103.55 | R11: REPORTED
A12: 43770 | B12: 43770 | C12: 2019 | D12: 11 | E12: CCIL_GSEC_REPO | F12: 1.1.2 Repo | G12: A. Settlement Systems | H12: Financial Market Infrastructures (FMIs) | I12: Wholesale Settlement (CCIL) | J12: Component | K12: 0.19 | L12: 2359754.7 | M12: 1.2419762e+09 | N12: c8 | O12: c9 | P12: 0.19 | Q12: 2359754.73 | R12: REPORTED
A13: 43770 | B13: 43770 | C13: 2019 | D13: 11 | E13: CCIL_GSEC_TOTAL | F13: 1.1 Govt. Securities Clearing (1.1.1 to 1.1.3) | G13: A. Settlement Systems | H13: Financial Market Infrastructures (FMIs) | I13: Wholesale Settlement (CCIL) | J13: Subtotal | K13: 1.01 | L13: 6869044.6 | M13: 6.8010342e+08 | N13: c4 | O13: c5 | P13: 1.01 | Q13: 6869044.58 | R13: REPORTED
... A24: 43770 | B24: 43770 | C24: 2019 | D24: 11 | E24: ECS_CREDIT | F24: 2.3 ECS Cr | G24: B. Payment Systems | H24: II Retail | I24: Retail Credit Transfers | J24: Component | K24: 0.17 | L24: 61.41 | M24: 36123.53 | N24: c28 | O24: c29 | P24: 0.17 | Q24: 61.41 | R24: REPORTED
A25: 43770 | B25: 43770 | C25: 2019 | D25: 11 | E25: ECS_DEBIT | F25: 3.2 ECS Dr | G25: B. Payment Systems | H25: II Retail | I25: Retail Debit Transfers | J25: Component | N25: c44 | O25: c45 | P25: - | Q25: - | R25: NOT_REPORTED
A26: 43770 | B26: 43770 | C26: 2019 | D26: 11 | E26: IMPS | F26: 2.4 IMPS | G26: B. Payment Systems | H26: II Retail | I26: Retail Credit Transfers | J26: Component | K26: 2280.75 | L26: 202903.64 | M26: 8896.36 | N26: c30 | O26: c31 | P26: 2280.75 | Q26: 202903.64 | R26: REPORTED
A27: 43770 | B27: 43770 | C27: 2019 | D27: 11 | E27: INTERNET_PAYMENTS_INTERBANK | F27: 2.2 Inter-bank @ | G27: A. Other Payment Channels | H27: II Retail | I27: Internet Banking Channels | J27: Component | K27: 2304.72 | L27: 1819547.5 | M27: 78948.74 | N27: c96 | O27: c97 | P27: 2304.72 | Q27: 1819547.47 | R27: REPORTED
A28: 43770 | B28: 43770 | C28: 2019 | D28: 11 | E28: INTERNET_PAYMENTS_INTRABANK | F28: 2.1 Intra-bank @ | G28: A. Other Payment Channels | H28: II Retail | I28: Internet Banking Channels | J28: Component | K28: 646.76 | L28: 2584753.7 | M28: 399646.49 | N28: c94 | O28: c95 | P28: 646.76 | Q28: 2584753.67 | R28: REPORTED
A29: 43770 | B29: 43770 | C29: 2019 | D29: 11 | E29: INTERNET_PAYMENTS_TOTAL | F29: 2 Internet Payments (Netbanking / Internet Browser Based) @ (2.1 to 2.2) | G29: A. Other Payment Channels | H29: II Retail | I29: Internet Banking Channels | J29: Category_Total | K29: 2951.47 | L29: 4404301.1 | M29: 149223.98 | N29: c92 | O29: c93 | P29: 2951.47 | Q29: 4404301.13 | R29: REPORTED
A30: 43770 | B30: 43770 | C30: 2019 | D30: 11 | E30: MICRO_ATM_AEPS_CASH | F30: 5.1 AePS @ | G30: B. ATMs | H30: II Retail | I30: Cash Withdrawals | J30: Component | K30: 339.83 | L30: 9648.11 | M30: 2839.1 | N30: c114 | O30: c115 | P30: 339.83 | Q30: 9648.11 | R30: REPORTED
A31: 43770 | B31: 43770 | C31: 2019 | D31: 11 | E31: MICRO_ATM_CASH_TOTAL | F31: 5 Cash Withrawal at Micro ATMs @ | G31: B. ATMs | H31: II Retail | I31: Cash Withdrawals | J31: Category_Total | K31: 339.83 | L31: 9648.11 | M31: 2839.1 | N31: c112 | O31: c113 | P31: 339.83 | Q31: 9648.11 | R31: REPORTED
A32: 43770 | B32: 43770 | C32: 2019 | D32: 11 | E32: MOBILE_PAYMENTS_INTERBANK | F32: 1.2 Inter-bank $ | G32: A. Other Payment Channels | H32: II Retail | I32: Mobile Banking Channels | J32: Component | K32: 12299.4 | L32: 374493.58 | M32: 3044.81 | N32: c90 | O32: c91 | P32: 12299.40 | Q32: 374493.58 | R32: REPORTED
A33: 43770 | B33: 43770 | C33: 2019 | D33: 11 | E33: MOBILE_PAYMENTS_INTRABANK | F33: 1.1 Intra-bank $ | G33: A. Other Payment Channels | H33: II Retail | I33: Mobile Banking Channels | J33: Component | K33: 1234.84 | L33: 96801.74 | M33: 7839.21 | N33: c88 | O33: c89 | P33: 1234.84 | Q33: 96801.74 | R33: REPORTED
A34: 43770 | B34: 43770 | C34: 2019 | D34: 11 | E34: MOBILE_PAYMENTS_TOTAL | F34: 1 Mobile Payments (mobile app based) (1.1 to 1.2) | G34: A. Other Payment Channels | H34: II Retail | I34: Mobile Banking Channels | J34: Category_Total | K34: 13534.23 | L34: 471295.32 | M34: 3482.25 | N34: c86 | O34: c87 | P34: 13534.23 | Q34: 471295.32 | R34: REPORTED
A35: 43770 | B35: 43770 | C35: 2019 | D35: 11 | E35: NACH_CREDIT | F35: 2.5 NACH Cr $ | G35: B. Payment Systems | H35: II Retail | I35: Retail Credit Transfers | J35: Component | K35: 706.05 | L35: 90940.69 | M35: 12880.21 | N35: c32 | O35: c33 | P35: 706.05 | Q35: 90940.69 | R35: REPORTED
A36: 43770 | B36: 43770 | C36: 2019 | D36: 11 | E36: NACH_DEBIT | F36: 3.3 NACH Dr $ | G36: B. Payment Systems | H36: II Retail | I36: Retail Debit Transfers | J36: Component | K36: 522.31 | L36: 52792.19 | M36: 10107.44 | N36: c46 | O36: c47 | P36: 522.31 | Q36: 52792.19 | R36: REPORTED
A37: 43770 | B37: 43770 | C37: 2019 | D37: 11 | E37: NEFT | F37: 2.6 NEFT | G37: B. Payment Systems | H37: II Retail | I37: Retail Credit Transfers | J37: Component | K37: 2194.59 | L37: 1734651.2 | M37: 79042.16 | N37: c34 | O37: c35 | P37: 2194.59 | Q37: 1734651.23 | R37: REPORTED
... A81: 43800 | B81: 43800 | C81: 2019 | D81: 12 | E81: ECS_CREDIT | F81: 2.3 ECS Cr | G81: B. Payment Systems | H81: II Retail | I81: Retail Credit Transfers | J81: Component | K81: 0.1 | L81: 53.35 | M81: 53350 | N81: c28 | O81: c29 | P81: 0.10 | Q81: 53.35 | R81: REPORTED
A82: 43800 | B82: 43800 | C82: 2019 | D82: 12 | E82: ECS_DEBIT | F82: 3.2 ECS Dr | G82: B. Payment Systems | H82: II Retail | I82: Retail Debit Transfers | J82: Component | N82: c44 | O82: c45 | P82: - | Q82: - | R82: NOT_REPORTED
A83: 43800 | B83: 43800 | C83: 2019 | D83: 12 | E83: IMPS | F83: 2.4 IMPS | G83: B. Payment Systems | H83: II Retail | I83: Retail Credit Transfers | J83: Component | K83: 2564.67 | L83: 210934.23 | M83: 8224.61 | N83: c30 | O83: c31 | P83: 2564.67 | Q83: 210934.23 | R83: REPORTED
A84: 43800 | B84: 43800 | C84: 2019 | D84: 12 | E84: INTERNET_PAYMENTS_INTERBANK | F84: 2.2 Inter-bank @ | G84: A. Other Payment Channels | H84: II Retail | I84: Internet Banking Channels | J84: Component | K84: 2299.45 | L84: 2024156.9 | M84: 88027.87 | N84: c96 | O84: c97 | P84: 2299.45 | Q84: 2024156.94 | R84: REPORTED
A85: 43800 | B85: 43800 | C85: 2019 | D85: 12 | E85: INTERNET_PAYMENTS_INTRABANK | F85: 2.1 Intra-bank @ | G85: A. Other Payment Channels | H85: II Retail | I85: Internet Banking Channels | J85: Component | K85: 694.78 | L85: 3510638.1 | M85: 505287.73 | N85: c94 | O85: c95 | P85: 694.78 | Q85: 3510638.11 | R85: REPORTED
A86: 43800 | B86: 43800 | C86: 2019 | D86: 12 | E86: INTERNET_PAYMENTS_TOTAL | F86: 2 Internet Payments (Netbanking / Internet Browser Based) @ (2.1 to 2.2) | G86: A. Other Payment Channels | H86: II Retail | I86: Internet Banking Channels | J86: Category_Total | K86: 2994.23 | L86: 5534795 | M86: 184848.69 | N86: c92 | O86: c93 | P86: 2994.23 | Q86: 5534795.05 | R86: REPORTED
A87: 43800 | B87: 43800 | C87: 2019 | D87: 12 | E87: MICRO_ATM_AEPS_CASH | F87: 5.1 AePS @ | G87: B. ATMs | H87: II Retail | I87: Cash Withdrawals | J87: Component | K87: 326.35 | L87: 9162.81 | M87: 2807.66 | N87: c114 | O87: c115 | P87: 326.35 | Q87: 9162.81 | R87: REPORTED
A88: 43800 | B88: 43800 | C88: 2019 | D88: 12 | E88: MICRO_ATM_CASH_TOTAL | F88: 5 Cash Withrawal at Micro ATMs @ | G88: B. ATMs | H88: II Retail | I88: Cash Withdrawals | J88: Category_Total | K88: 326.35 | L88: 9162.81 | M88: 2807.66 | N88: c112 | O88: c113 | P88: 326.35 | Q88: 9162.81 | R88: REPORTED
A89: 43800 | B89: 43800 | C89: 2019 | D89: 12 | E89: MOBILE_PAYMENTS_INTERBANK | F89: 1.2 Inter-bank $ | G89: A. Other Payment Channels | H89: II Retail | I89: Mobile Banking Channels | J89: Component | K89: 13041.49 | L89: 391663.33 | M89: 3003.21 | N89: c90 | O89: c91 | P89: 13041.49 | Q89: 391663.33 | R89: REPORTED
A90: 43800 | B90: 43800 | C90: 2019 | D90: 12 | E90: MOBILE_PAYMENTS_INTRABANK | F90: 1.1 Intra-bank $ | G90: A. Other Payment Channels | H90: II Retail | I90: Mobile Banking Channels | J90: Component | K90: 1280.66 | L90: 101678.83 | M90: 7939.56 | N90: c88 | O90: c89 | P90: 1280.66 | Q90: 101678.83 | R90: REPORTED
A91: 43800 | B91: 43800 | C91: 2019 | D91: 12 | E91: MOBILE_PAYMENTS_TOTAL | F91: 1 Mobile Payments (mobile app based) (1.1 to 1.2) | G91: A. Other Payment Channels | H91: II Retail | I91: Mobile Banking Channels | J91: Category_Total | K91: 14322.15 | L91: 493342.16 | M91: 3444.61 | N91: c86 | O91: c87 | P91: 14322.15 | Q91: 493342.16 | R91: REPORTED
A92: 43800 | B92: 43800 | C92: 2019 | D92: 12 | E92: NACH_CREDIT | F92: 2.5 NACH Cr $ | G92: B. Payment Systems | H92: II Retail | I92: Retail Credit Transfers | J92: Component | K92: 659.48 | L92: 78362.31 | M92: 11882.44 | N92: c32 | O92: c33 | P92: 659.48 | Q92: 78362.31 | R92: REPORTED
A93: 43800 | B93: 43800 | C93: 2019 | D93: 12 | E93: NACH_DEBIT | F93: 3.3 NACH Dr $ | G93: B. Payment Systems | H93: II Retail | I93: Retail Debit Transfers | J93: Component | K93: 531.45 | L93: 54171.42 | M93: 10193.14 | N93: c46 | O93: c47 | P93: 531.45 | Q93: 54171.42 | R93: REPORTED
...

Sheet PAYFLOW Dashboard
A1: PAYFLOW | Digital Payments Intelligence
A2: RBI Payment System Indicators • Coverage: November 2019 – July 2026
A3: Latest available month: July 2026 (partial year). 2026 is partial through July. UPI QR value indicator c141 is anomalous and excluded from reliable payment-value analysis; it is not used in this dashboard.
A5: LATEST-MONTH VOLUME (LAKH) | C5: LATEST-MONTH VALUE (₹ CRORE) | E5: UPI SHARE OF VOLUME | G5: MOM VOLUME GROWTH | I5: INFRA INDICATORS TRACKED
A6: =SUMIFS('Transaction Data'!$K$2:$K$4618,'Transaction Data'!$A$2:$A$4618,MAX('Transaction Data'!$A$2:$A$4618),'Transaction Data'!$E$2:$E$4618,"TOTAL_DIGITAL_PAYMENTS") -> 271816.8 | C6: =SUMIFS('Transaction Data'!$L$2:$L$4618,'Transaction Data'!$A$2:$A$4618,MAX('Transaction Data'!$A$2:$A$4618),'Transaction Data'!$E$2:$E$4618,"RTGS_TOTAL")+SUMIFS('Transaction Data'!$L$2:$L$4618,'Transaction Data'!$A$2:$A$4618,MAX('Transaction Data'!$A$2:$A$4618),'Transaction Data'!$E$2:$E$4618,"RETAIL_CREDIT_TRANSFERS_TOTAL")+SUMIFS('Transaction Data'!$L$2:$L$4618,'Transaction Data'!$A$2:$A$4618,MAX('Transaction Data'!$A$2:$A$4618),'Transaction Data'!$E$2:$E$4618,"DEBIT_TRANSFERS_TOTAL")+SUMIFS('Transaction Data'!$L$2:$L$4618,'Transaction Data'!$A$2:$A$4618,MAX('Transaction Data'!$A$2:$A$4618),'Transaction Data'!$E$2:$E$4618,"CARD_PAYMENTS_TOTAL")+SUMIFS('Transaction Data'!$L$2:$L$4618,'Transaction Data'!$A$2:$A$4618,MAX('Transaction Data'!$A$2:$A$4618),'Transaction Data'!$E$2:$E$4618,"PPI_TOTAL") -> 31436327 | E6: =SUMIFS('Transaction Data'!$K$2:$K$4618,'Transaction Data'!$A$2:$A$4618,MAX('Transaction Data'!$A$2:$A$4618),'Transaction Data'!$E$2:$E$4618,"UPI")/A6 -> 0.87037862 | G6: =A6/SUMIFS('Transaction Data'!$K$2:$K$4618,'Transaction Data'!$A$2:$A$4618,EDATE(MAX('Transaction Data'!$A$2:$A$4618),-1),'Transaction Data'!$E$2:$E$4618,"TOTAL_DIGITAL_PAYMENTS")-1 -> 0.038614191 | I6: {=SUMPRODUCT(('Infrastructure Data'!$E$2:$E$1054<>"")/COUNTIF('Infrastructure Data'!$E$2:$E$1054,'Infrastructure Data'!$E$2:$E$1054))} -> 13
A9: BUSINESS SIGNALS | JULY 2026
A10: ="UPI accounts for "&TEXT(E6,"0.0%")&" of July transaction volume, indicating a strongly UPI-led mix." -> UPI accounts for 87.0% of July transaction volume, indicating a strongly UPI-led mix.
A11: ="RTGS contributed "&TEXT(SUMIFS('Transaction Data'!$L$2:$L$4618,'Transaction Data'!$A$2:$A$4618,MAX('Transaction Data'!$A$2:$A$4618),'Transaction Data'!$E$2:$E$4618,"RTGS_TOTAL")/C6,"0.0%")&" of July transaction value." -> RTGS contributed 71.0% of July transaction value.
A12: ="Transaction volume grew "&TEXT(A6/SUMIFS('Transaction Data'!$K$2:$K$4618,'Transaction Data'!$A$2:$A$4618,EDATE(MAX('Transaction Data'!$A$2:$A$4618),-12),'Transaction Data'!$E$2:$E$4618,"TOTAL_DIGITAL_PAYMENTS")-1,"0.0%")&" year over year." -> Transaction volume grew 19.4% year over year.
A54: CHART SOURCE DATA — MONTHLY TOTALS | G54: LATEST-MONTH CATEGORY MIX — VOLUME
A55: Month | B55: Transaction volume (lakh) | D55: Month | E55: Transaction value (₹ crore) | G55: Official payment category | H55: Volume (lakh)
A56: =MIN('Transaction Data'!$A$2:$A$4618) -> 43770 | B56: =SUMIFS('Transaction Data'!$K$2:$K$4618,'Transaction Data'!$A$2:$A$4618,$A56,'Transaction Data'!$E$2:$E$4618,"TOTAL_DIGITAL_PAYMENTS") -> 29978.63 | D56: =A56 -> 43770 | E56: =SUMIFS('Transaction Data'!$L$2:$L$4618,'Transaction Data'!$A$2:$A$4618,$D56,'Transaction Data'!$E$2:$E$4618,"RTGS_TOTAL")+SUMIFS('Transaction Data'!$L$2:$L$4618,'Transaction Data'!$A$2:$A$4618,$D56,'Transaction Data'!$E$2:$E$4618,"RETAIL_CREDIT_TRANSFERS_TOTAL")+SUMIFS('Transaction Data'!$L$2:$L$4618,'Transaction Data'!$A$2:$A$4618,$D56,'Transaction Data'!$E$2:$E$4618,"DEBIT_TRANSFERS_TOTAL")+SUMIFS('Transaction Data'!$L$2:$L$4618,'Transaction Data'!$A$2:$A$4618,$D56,'Transaction Data'!$E$2:$E$4618,"CARD_PAYMENTS_TOTAL")+SUMIFS('Transaction Data'!$L$2:$L$4618,'Transaction Data'!$A$2:$A$4618,$D56,'Transaction Data'!$E$2:$E$4618,"PPI_TOTAL") -> 11092669 | G56: RTGS | H56: =SUMIFS('Transaction Data'!$K$2:$K$4618,'Transaction Data'!$A$2:$A$4618,MAX('Transaction Data'!$A$2:$A$4618),'Transaction Data'!$E$2:$E$4618,"RTGS_TOTAL") -> 333.1
A57: =EDATE(A56,1) -> 43800 | B57: =SUMIFS('Transaction Data'!$K$2:$K$4618,'Transaction Data'!$A$2:$A$4618,$A57,'Transaction Data'!$E$2:$E$4618,"TOTAL_DIGITAL_PAYMENTS") -> 32256.54 | D57: =A57 -> 43800 | E57: =SUMIFS('Transaction Data'!$L$2:$L$4618,'Transaction Data'!$A$2:$A$4618,$D57,'Transaction Data'!$E$2:$E$4618,"RTGS_TOTAL")+SUMIFS('Transaction Data'!$L$2:$L$4618,'Transaction Data'!$A$2:$A$4618,$D57,'Transaction Data'!$E$2:$E$4618,"RETAIL_CREDIT_TRANSFERS_TOTAL")+SUMIFS('Transaction Data'!$L$2:$L$4618,'Transaction Data'!$A$2:$A$4618,$D57,'Transaction Data'!$E$2:$E$4618,"DEBIT_TRANSFERS_TOTAL")+SUMIFS('Transaction Data'!$L$2:$L$4618,'Transaction Data'!$A$2:$A$4618,$D57,'Transaction Data'!$E$2:$E$4618,"CARD_PAYMENTS_TOTAL")+SUMIFS('Transaction Data'!$L$2:$L$4618,'Transaction Data'!$A$2:$A$4618,$D57,'Transaction Data'!$E$2:$E$4618,"PPI_TOTAL") -> 12958789 | G57: Retail credit transfers | H57: =SUMIFS('Transaction Data'!$K$2:$K$4618,'Transaction Data'!$A$2:$A$4618,MAX('Transaction Data'!$A$2:$A$4618),'Transaction Data'!$E$2:$E$4618,"RETAIL_CREDIT_TRANSFERS_TOTAL") -> 253061.29
A58: =EDATE(A57,1) -> 43831 | B58: =SUMIFS('Transaction Data'!$K$2:$K$4618,'Transaction Data'!$A$2:$A$4618,$A58,'Transaction Data'!$E$2:$E$4618,"TOTAL_DIGITAL_PAYMENTS") -> 33631.79 | D58: =A58 -> 43831 | E58: =SUMIFS('Transaction Data'!$L$2:$L$4618,'Transaction Data'!$A$2:$A$4618,$D58,'Transaction Data'!$E$2:$E$4618,"RTGS_TOTAL")+SUMIFS('Transaction Data'!$L$2:$L$4618,'Transaction Data'!$A$2:$A$4618,$D58,'Transaction Data'!$E$2:$E$4618,"RETAIL_CREDIT_TRANSFERS_TOTAL")+SUMIFS('Transaction Data'!$L$2:$L$4618,'Transaction Data'!$A$2:$A$4618,$D58,'Transaction Data'!$E$2:$E$4618,"DEBIT_TRANSFERS_TOTAL")+SUMIFS('Transaction Data'!$L$2:$L$4618,'Transaction Data'!$A$2:$A$4618,$D58,'Transaction Data'!$E$2:$E$4618,"CARD_PAYMENTS_TOTAL")+SUMIFS('Transaction Data'!$L$2:$L$4618,'Transaction Data'!$A$2:$A$4618,$D58,'Transaction Data'!$E$2:$E$4618,"PPI_TOTAL") -> 12537396 | G58: Retail debit transfers | H58: =SUMIFS('Transaction Data'!$K$2:$K$4618,'Transaction Data'!$A$2:$A$4618,MAX('Transaction Data'!$A$2:$A$4618),'Transaction Data'!$E$2:$E$4618,"DEBIT_TRANSFERS_TOTAL") -> 2100.53
A59: =EDATE(A58,1) -> 43862 | B59: =SUMIFS('Transaction Data'!$K$2:$K$4618,'Transaction Data'!$A$2:$A$4618,$A59,'Transaction Data'!$E$2:$E$4618,"TOTAL_DIGITAL_PAYMENTS") -> 32895.25 | D59: =A59 -> 43862 | E59: =SUMIFS('Transaction Data'!$L$2:$L$4618,'Transaction Data'!$A$2:$A$4618,$D59,'Transaction Data'!$E$2:$E$4618,"RTGS_TOTAL")+SUMIFS('Transaction Data'!$L$2:$L$4618,'Transaction Data'!$A$2:$A$4618,$D59,'Transaction Data'!$E$2:$E$4618,"RETAIL_CREDIT_TRANSFERS_TOTAL")+SUMIFS('Transaction Data'!$L$2:$L$4618,'Transaction Data'!$A$2:$A$4618,$D59,'Transaction Data'!$E$2:$E$4618,"DEBIT_TRANSFERS_TOTAL")+SUMIFS('Transaction Data'!$L$2:$L$4618,'Transaction Data'!$A$2:$A$4618,$D59,'Transaction Data'!$E$2:$E$4618,"CARD_PAYMENTS_TOTAL")+SUMIFS('Transaction Data'!$L$2:$L$4618,'Transaction Data'!$A$2:$A$4618,$D59,'Transaction Data'!$E$2:$E$4618,"PPI_TOTAL") -> 11578729 | G59: Card payments | H59: =SUMIFS('Transaction Data'!$K$2:$K$4618,'Transaction Data'!$A$2:$A$4618,MAX('Transaction Data'!$A$2:$A$4618),'Transaction Data'!$E$2:$E$4618,"CARD_PAYMENTS_TOTAL") -> 7068.23
A60: =EDATE(A59,1) -> 43891 | B60: =SUMIFS('Transaction Data'!$K$2:$K$4618,'Transaction Data'!$A$2:$A$4618,$A60,'Transaction Data'!$E$2:$E$4618,"TOTAL_DIGITAL_PAYMENTS") -> 29266.86 | D60: =A60 -> 43891 | E60: =SUMIFS('Transaction Data'!$L$2:$L$4618,'Transaction Data'!$A$2:$A$4618,$D60,'Transaction Data'!$E$2:$E$4618,"RTGS_TOTAL")+SUMIFS('Transaction Data'!$L$2:$L$4618,'Transaction Data'!$A$2:$A$4618,$D60,'Transaction Data'!$E$2:$E$4618,"RETAIL_CREDIT_TRANSFERS_TOTAL")+SUMIFS('Transaction Data'!$L$2:$L$4618,'Transaction Data'!$A$2:$A$4618,$D60,'Transaction Data'!$E$2:$E$4618,"DEBIT_TRANSFERS_TOTAL")+SUMIFS('Transaction Data'!$L$2:$L$4618,'Transaction Data'!$A$2:$A$4618,$D60,'Transaction Data'!$E$2:$E$4618,"CARD_PAYMENTS_TOTAL")+SUMIFS('Transaction Data'!$L$2:$L$4618,'Transaction Data'!$A$2:$A$4618,$D60,'Transaction Data'!$E$2:$E$4618,"PPI_TOTAL") -> 15024754 | G60: Prepaid instruments | H60: =SUMIFS('Transaction Data'!$K$2:$K$4618,'Transaction Data'!$A$2:$A$4618,MAX('Transaction Data'!$A$2:$A$4618),'Transaction Data'!$E$2:$E$4618,"PPI_TOTAL") -> 9253.65
A61: =EDATE(A60,1) -> 43922 | B61: =SUMIFS('Transaction Data'!$K$2:$K$4618,'Transaction Data'!$A$2:$A$4618,$A61,'Transaction Data'!$E$2:$E$4618,"TOTAL_DIGITAL_PAYMENTS") -> 23604.69 | D61: =A61 -> 43922 | E61: =SUMIFS('Transaction Data'!$L$2:$L$4618,'Transaction Data'!$A$2:$A$4618,$D61,'Transaction Data'!$E$2:$E$4618,"RTGS_TOTAL")+SUMIFS('Transaction Data'!$L$2:$L$4618,'Transaction Data'!$A$2:$A$4618,$D61,'Transaction Data'!$E$2:$E$4618,"RETAIL_CREDIT_TRANSFERS_TOTAL")+SUMIFS('Transaction Data'!$L$2:$L$4618,'Transaction Data'!$A$2:$A$4618,$D61,'Transaction Data'!$E$2:$E$4618,"DEBIT_TRANSFERS_TOTAL")+SUMIFS('Transaction Data'!$L$2:$L$4618,'Transaction Data'!$A$2:$A$4618,$D61,'Transaction Data'!$E$2:$E$4618,"CARD_PAYMENTS_TOTAL")+SUMIFS('Transaction Data'!$L$2:$L$4618,'Transaction Data'!$A$2:$A$4618,$D61,'Transaction Data'!$E$2:$E$4618,"PPI_TOTAL") -> 8241148.3
